Workbook

Sheet Sheet1
A1: PENGESAHAN KEHADIRAN PEGAWAI BAGI MAJLIS MMR JASA DIKENANG KPA (GAJI)
A3: BIL | B3: NO TEN | C3: PKT | D3: NAMA PENUH | E3: PASUKAN | F3: JAWATAN | G3: MENU | I3: PASANGAN | J3: MENU PASANGAN | K3: CATATAN
AA4: NO TELEFON BIMBIT | AB4: JANTINA
A5: 1 | B5: 3004463 | C5: BRIG JEN | D5: ZAMZURI BIN HARUN | E5: BPA - UGAT | F5: PENGARAH | G5: DAGING | H5: P3004463 | I5: PN ZURYATI BINTI ZULKIFLI | J5: AYAM | AA5: 0126210046 / 0129210046 | AB5: L
A6: 2 | B6: 3003652 | C6: BRIG JEN | D6: AZAMAN BIN JAAFAR | E6: MK TD - CWG P&P | F6: KETUA PENGARAH BELANJAWAN | G6: KAMBING | H6: P3003652 | I6: PN ARDINA SURIA BTE ABU BAKAR | J6: DAGING | AA6: 012-2442182 | AB6: L
A7: 3 | B7: 3005059 | C7: KOL | D7: ZULKIFLE BIN HASHIM | E7: MK TD - CSM | F7: PENGARAH BELANJAWAN | G7: DAGING | H7: P3005059 | I7: PN RAHIMAH BINTI ALAM SAH | J7: DAGING | AA7: 012-6636811 | AB7: L
A8: 4 | B8: 3005715 | C8: KOL | D8: MOHD LUTPI TAUFIK BIN CHE MAT MIN | E8: BPA - UGAT | F8: TIMB PENGARAH | G8: KAMBING | H8: P3005715 | I8: PN TENGKU ASMA IZANI BINTI DATO’ TENGKU AZIZ | J8: IKAN | AA8: 012-3996017 | AB8: L
A9: 5 | B9: 3005397 | C9: LT KOL | D9: NORAZILENA BINTI MOHAMAD NOR | E9: MK TD - CWG P&P | F9: PS 1 KEWANGAN | G9: KAMBING | H9: P3005397 | I9: - | AA9: 012-6393950 | AB9: P
A10: 6 | B10: 3006393 | C10: LT KOL | D10: JAMAL BIN SAPRI | E10: MK PMBTD | F10: PS 1 BELANJAWAN | G10: KAMBING | H10: P3006393 | I10: DR SALIMAH BINTI HJ OTHMAN | J10: IKAN | AA10: 019-2364654 | AB10: L
A11: 7 | B11: 3006672 | C11: LT KOL | D11: AZARUL AZUAN BIN ABDULLAH | E11: MK ATM - SEK | F11: PS 1 KEWANGAN | G11: KAMBING | H11: P3006672 | I11: PN RAPIDAH BINTI MAZLAN | J11: DAGING | AA11: 012-2886720 | AB11: L
A12: 8 | B12: 3006696 | C12: LT KOL | D12: MOHD AZIZAN BIN MUSTAPHA | E12: MK PLDTD | F12: PS 1 BELANJAWAN | G12: DAGING | H12: P3006696 | I12: PUAN ROHAYU BINTI IBRAHIM | J12: IKAN | AA12: 013-9837644 | AB12: L
A13: 9 | B13: 3007255 | C13: LT KOL | D13: AZHAR BIN AHMAD | E13: BPA - UGAT | F13: PS 1 TURUS | G13: IKAN | H13: P3007255 | I13: PN FADHILAH BINTI AHMAD | J13: AYAM | AA13: 019-9157255 | AB13: L
A14: 10 | B14: 3009651 | C14: LT KOL | D14: MOHD AZIZI BIN AHMAD | E14: MK PMTTD | F14: PS 1 BELANJAWAN | G14: IKAN | H14: P3009651 | I14: PUAN NORZUNAIRAH BINTI MOHAMED NOR | J14: KAMBING | AA14: 012-6636811 | AB14: L
A15: 11 | B15: 3007529 | C15: LT KOL | D15: IZWAN BIN ISMAIL | E15: MK TD - CSM | F15: PS 1 KEWANGAN | G15: DAGING | H15: P3007529 | I15: PN SHARINA YUSNEEN BINTI KAMARUDDIN | J15: DAGING | AA15: 019-3597529 | AB15: L
A16: 12 | B16: 3010189 | C16: LT KOL | D16: ZULKARNAIN BIN YUSUF | E16: BADSA | F16: KETUA AUDIT BERSAMA | G16: DAGING | H16: P3010189 | I16: - | AA16: 012-3390189 | AB16: L
A17: 13 | B17: 3008216 | C17: LT KOL | D17: NORAZLINA BTE IBRAHIM | E17: BPA - UGAT | F17: PS 1 AKAUN | G17: IKAN | H17: P3008216 | I17: - | AA17: 013-3866248 | AB17: P
A18: 14 | B18: 3010206 | C18: LT KOL | D18: NORSYAZURA BTE MUSA | E18: BADSA | F18: PS 1 KAJIAN | G18: DAGING | H18: P3010206 | I18: EN MOHAMAD JOHARI BIN ISMAIL | J18: DAGING | AA18: 012-6161017 | AB18: P
A19: 15 | B19: 3009693 | C19: MEJ | D19: ZULKARNAIN BIN AMIR | E19: BPA - UGAT | F19: PS 1 BAYARAN | G19: DAGING | H19: P3009693 | I19: PN ZANARIAH BINTI IBRAHIM | J19: IKAN | AA19: 019-9369693 | AB19: L
A20: 16 | B20: 3008035 | C20: MEJ | D20: MOHAMAD HAZRI BIN HAMZAH | E20: MK ATM - BPKP | F20: PS 1 KEWANGAN | G20: IKAN | H20: P3008035 | I20: PN AZRINA BINTI MOHAMAD HEPNI | J20: AYAM | AA20: 019-2818035 | AB20: L
A21: 17 | B21: 3005934 | C21: LT KOL | D21: ABDULLAH BIN AYOB | E21: ATD - KOLEJ PTT | F21: JURULATIH KANAN | G21: KAMBING | H21: P3005934 | I21: - | AA21: 019-2773749 | AB21: L
A22: 18 | B22: 3006480 | C22: LT KOL | D22: NORDIN BIN AWANG | E22: BPA - KEBAJIKAN | F22: PS 2 TKAT | G22: DAGING | H22: P3006480 | I22: PN NORZURA BTE MOHAMED | J22: DAGING | AA22: 019-2866709 | AB22: L
A23: 19 | B23: 3007186 | C23: LT KOL | D23: ANTHONY AK UNGOP | E23: MK BGD KE-31 INF | F23: PS 2 GAJI/ BELANJAWAN | G23: AYAM | H23: P3007186 | I23: - | AA23: 019-8157186 | AB23: L
A24: 20 | B24: 3007228 | C24: LT KOL | D24: NAZIRUDDIN BIN ISMAIL | E24: BPA - UGAT | F24: PS 2 PEMERIKSAAN | G24: KAMBING | H24: P3007228 | I24: PN ISMAWATI BTE IDRIS | J24: IKAN | AA24: 019-3935967 | AB24: L
A25: 21 | B25: 3008083 | C25: LT KOL | D25: YOONG SOON KIONG | E25: BPA-CTK | F25: PS 2 RANCANG A3 | G25: IKAN | H25: P3008083 | I25: - | AA25: 016-7795115 | AB25: L
A26: 22 | B26: 3006374 | C26: MEJ | D26: YUSRI BIN DARUS | E26: MK 2 DIV | F26: PS 2 BELANJAWAN | G26: DAGING | H26: P3006374 | I26: - | K26: LATEST - ISTERI X HADIR | AA26: 017-4036270 | AB26: L
A27: 23 | B27: 3006377 | C27: MEJ | D27: ROSMAZIA BTE MUSTAPHA | E27: PU SENDAYAN | F27: PS 2 GAJI | G27: IKAN | H27: P3006377 | I27: - | AA27: 019-2703285 | AB27: P
A28: 24 | B28: 3006690 | C28: MEJ | D28: KU NORAZLINI BTE MOHD ALI | E28: MTD | F28: PEGAWAI GAJI | G28: IKAN | H28: P3006690 | I28: - | AA28: 013-3880206 | AB28: P
A29: 25 | B29: 3006807 | C29: MEJ | D29: JUHAIRI RAFHAN BIN JASMANI | E29: MK ATM - MSAT (PBAT) | F29: BENDAHARI PBAT | G29: KAMBING | H29: P3006807 | I29: MEJ MAZIAH BTE ABDUL MANAF | AA29: 012-3207329 | AB29: L
A30: 26 | B30: 3006810 | C30: MEJ | D30: MAZIAH BTE ABDUL MANAF | E30: PUSPAHANAS | F30: PENGURUS WISMA | G30: DAGING | H30: P3006810 | I30: MEJ JUHAIRI RAFHAN BIN JASMANI (3006807) | AA30: 012-3290079/ 019-3356810 | AB30: P
A31: 27 | B31: 3007993 | C31: MEJ | D31: AHMAD LUFTI BIN BABA | E31: BPA - UGAT | F31: PS 2 TADBIR | G31: AYAM | H31: P3007993 | I31: PN NURUL AIN BINTI ZAKARIA | J31: IKAN | AA31: 013-2970933 | AB31: L
A32: 28 | B32: 3007997 | C32: MEJ | D32: ASRUL BIN BAHAR | E32: MAWILUD 2 | F32: PS 2 GAJI | G32: DAGING | H32: P3007997 | I32: - | AA32: 019-5819848 | AB32: L
A33: 29 | B33: 3008001 | C33: MEJ | D33: BADRUL HISHAM BIN MOHD SOHAIMI | E33: MK TD - CSM | F33: PS 2 KEWANGAN | G33: IKAN | H33: P3008001 | I33: PN NURHUDA BINTI ABD RAHIM | J33: AYAM | AA33: 019-9808001 | AB33: L
A34: 30 | B34: 3008032 | C34: MEJ | D34: MOHD FAIZAL BIN ABDUL WAHID | E34: PULADA | F34: PEG ABM | G34: AYAM | H34: P3008032 | I34: - | AA34: 012-3458032 | AB34: L
A35: 31 | B35: 3008056 | C35: MEJ | D35: NATASYA AINI BTE OSMAN | E35: MAWILLUD 1 | F35: PS 2 GAJI | G35: DAGING | H35: P3008056 | I35: - | AA35: 019-2778499 | AB35: P
A36: 32 | B36: 3008124 | C36: MEJ | D36: MAHATHIR BIN DAUD | E36: MK 4 BGD (MEK) | F36: PS 2 BELANJAWAN | G36: DAGING | H36: P3008124 | I36: - | AA36: 012-8064838 | AB36: L
A37: 33 | B37: 3008219 | C37: MEJ | D37: NORZIEANA BTE ISMAIL | E37: MK ATM - SEK | F37: PS 2 KEWANGAN | G37: IKAN | H37: P3008219 | I37: - | AA37: 012-6293911 | AB37: P
A38: 34 | B38: 3008445 | C38: MEJ | D38: IQTIYANIE MARLITA BTE MOHD GANI | E38: MK ATM - SEK | F38: PS 2 PERSONAL EMOLUMEN (PE) | G38: IKAN | H38: P3008445 | I38: - | AA38: 012-2748747 | AB38: P
A39: 35 | B39: 3008476 | C39: MEJ | D39: MOHD ISHAR BIN AHMAD ROBANI | E39: BOPKP | F39: PS 2 GAJI | G39: AYAM | H39: P3008476 | I39: - | AA39: 019-3558476 | AB39: L
A40: 36 | B40: 3008508 | C40: MEJ | D40: NORAPIDAH BTE ABU BAKAR | E40: HAT TUANKU MIZAN | F40: PS 2 KEWANGAN | G40: KAMBING | H40: P3008508 | I40: - | AA40: 019-2718508 | AB40: P
A41: 37 | B41: 3008905 | C41: MEJ | D41: HARTINI BTE MD AMIN | E41: BPA - UGAT | F41: PEMEGANG PANJAR ATM 101 | G41: IKAN | H41: P3008905 | I41: - | AA41: 019-2009985 | AB41: P
...

Sheet Sheet2
A1: BIL | B1: NO TEN | C1: NO TEN | D1: PKT | E1: NAMA PENUH | F1: PASUKAN | G1: JAWATAN | H1: MENU
A2: 1 | B2: 3004463 | C2: 3004463 | D2: BRIG JEN | E2: ZAMZURI BIN HARUN | F2: BPA - UGAT | G2: PENGARAH | H2: DAGING | X2: 0126210046 / 0129210046 | Y2: L
A3: 2 | B3: 3003652 | C3: 3003652 | D3: BRIG JEN | E3: AZAMAN BIN JAAFAR | F3: MK TD - CWG P&P | G3: KETUA PENGARAH BELANJAWAN | H3: KAMBING | X3: 012-2442182 | Y3: L
A4: 3 | B4: 3005059 | C4: 3005059 | D4: KOL | E4: ZULKIFLE BIN HASHIM | F4: MK TD - CSM | G4: PENGARAH BELANJAWAN | H4: DAGING | X4: 012-6636811 | Y4: L
A5: 4 | B5: 3005715 | C5: 3005715 | D5: KOL | E5: MOHD LUTPI TAUFIK BIN CHE MAT MIN | F5: BPA - UGAT | G5: TIMB PENGARAH | H5: KAMBING | X5: 012-3996017 | Y5: L
A6: 5 | B6: 3005397 | C6: 3005397 | D6: LT KOL | E6: NORAZILENA BINTI MOHAMAD NOR | F6: MK TD - CWG P&P | G6: PS 1 KEWANGAN | H6: KAMBING | X6: 012-6393950 | Y6: P
A7: 6 | B7: 3006393 | C7: 3006393 | D7: LT KOL | E7: JAMAL BIN SAPRI | F7: MK PMBTD | G7: PS 1 BELANJAWAN | H7: KAMBING | X7: 019-2364654 | Y7: L
A8: 7 | B8: 3006672 | C8: 3006672 | D8: LT KOL | E8: AZARUL AZUAN BIN ABDULLAH | F8: MK ATM - SEK | G8: PS 1 KEWANGAN | H8: KAMBING | X8: 012-2886720 | Y8: L
A9: 8 | B9: 3006696 | C9: 3006696 | D9: LT KOL | E9: MOHD AZIZAN BIN MUSTAPHA | F9: MK PLDTD | G9: PS 1 BELANJAWAN | H9: DAGING | X9: 013-9837644 | Y9: L
A10: 9 | B10: 3007255 | C10: 3007255 | D10: LT KOL | E10: AZHAR BIN AHMAD | F10: BPA - UGAT | G10: PS 1 TURUS | H10: IKAN | X10: 019-9157255 | Y10: L
A11: 10 | B11: 3009651 | C11: 3009651 | D11: LT KOL | E11: MOHD AZIZI BIN AHMAD | F11: MK PMTTD | G11: PS 1 BELANJAWAN | H11: IKAN | X11: 012-6636811 | Y11: L
A12: 11 | B12: 3007529 | C12: 3007529 | D12: LT KOL | E12: IZWAN BIN ISMAIL | F12: MK TD - CSM | G12: PS 1 KEWANGAN | H12: DAGING | X12: 019-3597529 | Y12: L
A13: 12 | B13: 3010189 | C13: 3010189 | D13: LT KOL | E13: ZULKARNAIN BIN YUSUF | F13: BADSA | G13: KETUA AUDIT BERSAMA | H13: DAGING | X13: 012-3390189 | Y13: L
... A161: 160 | B161: 7539373 | C161: 7539373 | D161: LT M | E161: RAIZARUL AZFAR BIN RUSLAN | F161: 19 RAMD (MEK) | G161: PEG GAJI | H161: DAGING | X161: 017-5242406 | Y161: L
A162: 161 | B162: P3006393 | C162: 3006393 | E162: DR SALIMAH BINTI HJ OTHMAN | H162: IKAN
A163: 162 | B163: P3010206 | C163: 3010206 | E163: EN MOHAMAD JOHARI BIN ISMAIL | H163: DAGING
A164: 163 | B164: P3015874 | C164: 3015874 | E164: KAPT ASHOKAN A/L NACHIMUTHU (3015363) | H164: AYAM
A165: 164 | B165: P3013928 | C165: 3013928 | E165: KAPT AZZRUL HAFIEZ BIN HUSSIN
A166: 165 | B166: P3013049 | C166: 3013049 | E166: KAPT MUHAMMAD AFIQ BIN ALIAS BHAROM | H166: KAMBING
A167: 166 | B167: P7520874 | C167: 7520874 | E167: KAPT MUHAMMAD HANIS BIN ABDUL TUDM | H167: DAGING
A168: 167 | B168: P3013954 | C168: 3013954 | E168: KAPT NOORMAS AIMAN BIN NOOR RIZAN | H168: IKAN
A169: 168 | B169: P7510166 | C169: 7510166 | E169: KAPT NOR NIZAMIAH BINTI OTHMAN | H169: DAGING
A170: 169 | B170: P7526905 | C170: 7526905 | E170: KAPT NURFARAHIN BINTI MOHD MOKHTAR
A171: 170 | B171: P7533192 | C171: 7533192 | E171: KAPT SANUSI - UGAT
A172: 171 | B172: P7538359 | C172: 7538359 | E172: LT MOHAMAD DARWIS AIMAN BIN SAHI SULTAN | H172: DAGING
A173: 172 | B173: P3014790 | C173: 3014790 | E173: LT SITI NURAISYAH BINTI SIDEK (7533192)
A174: 173 | B174: P3013038 | C174: 3013038 | E174: MAHFUZAH BINTI ABD GANI | H174: AYAM
A175: 174 | B175: P3010287 | C175: 3010287 | E175: MEJ AIZAT (KOMPUTER)
A176: 175 | B176: P3009717 | C176: 3009717 | E176: MEJ AZHARI BIN CHE RUS
A177: 176 | B177: P3006810 | C177: 3006810 | E177: MEJ JUHAIRI RAFHAN BIN JASMANI (3006807)
A178: 177 | B178: P3011701 | C178: 3011701 | E178: MEJ MAIZIATUL LIYANA (GAJI)
A179: 178 | B179: P3006807 | C179: 3006807 | E179: MEJ MAZIAH BTE ABDUL MANAF
A180: 179 | B180: P7517972 | C180: 7517972 | E180: MEJ MOHD FAUDZI BIN CHE HASHIM | H180: DAGING
A181: 180 | B181: P3012281 | C181: 3012281 | E181: MEJ MUHAMMAD AIZAT BIN ABDUL RAHIM (3011455) | H181: IKAN
A182: 181 | B182: P3009154 | C182: 3009154 | E182: MEJ NORAFLINA BINTI MOHD ANUAR
A183: 182 | B183: P7526077 | C183: 7526077 | E183: MEJ NURAKMAL BIN HASSAN | H183: DAGING
A184: 183 | B184: P3010205 | C184: 3010205 | E184: MEJ SHAHFIZAL BIN KHAIRUDIN | H184: KAMBING
A185: 184 | B185: P3016919 | C185: 3016919 | E185: MUHAMMAD EMIR DANIAL BIN MUHD BAHARUDDIN | H185: KAMBING
A186: 185 | B186: P7520898 | C186: 7520898 | E186: MUHAMMAD IHSAN BIN MOHD ZAINUDDIN | H186: KAMBING
A187: 186 | B187: P3016936 | C187: 3016936 | E187: PN AINNURNADHIRAH BINTI ABDUL SAMAD | H187: IKAN
...

Sheet LIST BY MEJA
B2: SENARAI NAMA MENGIKUT MEJA (VIP)
B4: BIL | C4: NAMA | D4: MENU | E4: KERUSI
B5: 1 | C5: =VLOOKUP(E5,'LIST KEHADIRAN'!A:H,5,FALSE) -> MEJ JEN ROBAÍ BIN RAHMAT | D5: =VLOOKUP(E5,'LIST KEHADIRAN'!A:H,8,FALSE) -> IKAN | E5: 1
B6: 2 | C6: =VLOOKUP(E6,'LIST KEHADIRAN'!A:H,5,FALSE) -> PN ZUZANAH BTE ALI | D6: =VLOOKUP(E6,'LIST KEHADIRAN'!A:H,8,FALSE) -> DAGING | E6: 2
B7: 3 | C7: =VLOOKUP(E7,'LIST KEHADIRAN'!A:H,5,FALSE) -> BRIG JEN ZAMZURI BIN HARUN | D7: =VLOOKUP(E7,'LIST KEHADIRAN'!A:H,8,FALSE) -> DAGING | E7: 3
B8: 4 | C8: =VLOOKUP(E8,'LIST KEHADIRAN'!A:H,5,FALSE) -> PN ZURYATI BINTI ZULKIFLI | D8: =VLOOKUP(E8,'LIST KEHADIRAN'!A:H,8,FALSE) -> AYAM | E8: 4
B9: 5 | C9: =VLOOKUP(E9,'LIST KEHADIRAN'!A:H,5,FALSE) -> BRIG JEN AZAMAN BIN JAAFAR | D9: =VLOOKUP(E9,'LIST KEHADIRAN'!A:H,8,FALSE) -> KAMBING | E9: 5
B10: 6 | C10: =VLOOKUP(E10,'LIST KEHADIRAN'!A:H,5,FALSE) -> PN ARDINA SURIA BTE ABU BAKAR | D10: =VLOOKUP(E10,'LIST KEHADIRAN'!A:H,8,FALSE) -> DAGING | E10: 6
B11: 7 | C11: =VLOOKUP(E11,'LIST KEHADIRAN'!A:H,5,FALSE) -> KOL MOHD LUTPI TAUFIK BIN CHE MAT MIN | D11: =VLOOKUP(E11,'LIST KEHADIRAN'!A:H,8,FALSE) -> KAMBING | E11: 7
B12: 8 | C12: =VLOOKUP(E12,'LIST KEHADIRAN'!A:H,5,FALSE) -> PN TENGKU ASMA IZANI BINTI DATO’ TENGKU AZIZ | D12: =VLOOKUP(E12,'LIST KEHADIRAN'!A:H,8,FALSE) -> IKAN | E12: 8
B13: 9 | C13: =VLOOKUP(E13,'LIST KEHADIRAN'!A:H,5,FALSE) -> KOL ZULKIFLE BIN HASHIM | D13: =VLOOKUP(E13,'LIST KEHADIRAN'!A:H,8,FALSE) -> DAGING | E13: 9
B14: 10 | C14: =VLOOKUP(E14,'LIST KEHADIRAN'!A:H,5,FALSE) -> PN RAHIMAH BINTI ALAM SAH | D14: =VLOOKUP(E14,'LIST KEHADIRAN'!A:H,8,FALSE) -> DAGING | E14: 10
B15: 11 | C15: =VLOOKUP(E15,'LIST KEHADIRAN'!A:H,5,FALSE) -> LT KOL AZHAR BIN AHMAD | D15: =VLOOKUP(E15,'LIST KEHADIRAN'!A:H,8,FALSE) -> IKAN | E15: 11
B16: 12 | C16: =VLOOKUP(E16,'LIST KEHADIRAN'!A:H,5,FALSE) -> PN FADHILAH BINTI AHMAD | D16: =VLOOKUP(E16,'LIST KEHADIRAN'!A:H,8,FALSE) -> AYAM | E16: 12
B18: SENARAI NAMA MENGIKUT MEJA (A)
B20: BIL | C20: NAMA | D20: MENU | E20: KERUSI
B21: 1 | C21: =VLOOKUP(E21,'LIST KEHADIRAN'!A:H,5,FALSE) -> MEJ ROSMAZIA BTE MUSTAPHA | D21: =VLOOKUP(E21,'LIST KEHADIRAN'!A:H,8,FALSE) -> IKAN | E21: AR1
B22: 2 | C22: =VLOOKUP(E22,'LIST KEHADIRAN'!A:H,5,FALSE) -> MEJ KU NORAZLINI BTE MOHD ALI | D22: =VLOOKUP(E22,'LIST KEHADIRAN'!A:H,8,FALSE) -> IKAN | E22: AR2
B23: 3 | C23: =VLOOKUP(E23,'LIST KEHADIRAN'!A:H,5,FALSE) -> MEJ NATASYA AINI BTE OSMAN | D23: =VLOOKUP(E23,'LIST KEHADIRAN'!A:H,8,FALSE) -> DAGING | E23: AR3
B24: 4 | C24: =VLOOKUP(E24,'LIST KEHADIRAN'!A:H,5,FALSE) -> KAPT NUR DIYANA BTE CHE OMAR | D24: =VLOOKUP(E24,'LIST KEHADIRAN'!A:H,8,FALSE) -> KAMBING | E24: AR4
B25: 5 | C25: =VLOOKUP(E25,'LIST KEHADIRAN'!A:H,5,FALSE) -> KAPT SUNAINI BINTI MOHD ALI | D25: =VLOOKUP(E25,'LIST KEHADIRAN'!A:H,8,FALSE) -> AYAM | E25: AR5
B26: 6 | C26: =VLOOKUP(E26,'LIST KEHADIRAN'!A:H,5,FALSE) -> KAPT NUR IZZATI BINTI ZAIDEL | D26: =VLOOKUP(E26,'LIST KEHADIRAN'!A:H,8,FALSE) -> DAGING | E26: AR6
B27: 7 | C27: =VLOOKUP(E27,'LIST KEHADIRAN'!A:H,5,FALSE) -> MEJ MUHAMMAD AIZAT BIN ABDUL RAHIM | D27: =VLOOKUP(E27,'LIST KEHADIRAN'!A:H,8,FALSE) -> IKAN | E27: AR7
B28: 8 | C28: =VLOOKUP(E28,'LIST KEHADIRAN'!A:H,5,FALSE) -> KAPT MOHAMAD A'RIF BIN MOHAMED NOR | D28: =VLOOKUP(E28,'LIST KEHADIRAN'!A:H,8,FALSE) -> DAGING | E28: AR8
B29: 9 | C29: =VLOOKUP(E29,'LIST KEHADIRAN'!A:H,5,FALSE) -> #N/A | D29: =VLOOKUP(E29,'LIST KEHADIRAN'!A:H,8,FALSE) -> #N/A | E29: AR9
B30: 10 | C30: =VLOOKUP(E30,'LIST KEHADIRAN'!A:H,5,FALSE) -> #N/A | D30: =VLOOKUP(E30,'LIST KEHADIRAN'!A:H,8,FALSE) -> #N/A | E30: AR10
B31: 11 | C31: =VLOOKUP(E31,'LIST KEHADIRAN'!A:H,5,FALSE) -> #N/A | D31: =VLOOKUP(E31,'LIST KEHADIRAN'!A:H,8,FALSE) -> #N/A | E31: AR11
B32: 12 | C32: =VLOOKUP(E32,'LIST KEHADIRAN'!A:H,5,FALSE) -> LT SYED UMAR BIN SYED KHAIRULAMAN BENYAHYA | D32: =VLOOKUP(E32,'LIST KEHADIRAN'!A:H,8,FALSE) -> AYAM | E32: AR12
... B58: 46 | C58: =VLOOKUP(E58,'LIST KEHADIRAN'!A:H,5,FALSE) -> #N/A | D58: =VLOOKUP(E58,'LIST KEHADIRAN'!A:H,8,FALSE) -> #N/A | E58: AL19
B61: SENARAI NAMA MENGIKUT MEJA (B)
B63: BIL | C63: NAMA | D63: MENU | E63: KERUSI
B64: 1 | C64: =VLOOKUP(E64,'LIST KEHADIRAN'!A:H,5,FALSE) -> LT KOL JAMAL BIN SAPRI | D64: =VLOOKUP(E64,'LIST KEHADIRAN'!A:H,8,FALSE) -> KAMBING | E64: BR1
B65: 2 | C65: =VLOOKUP(E65,'LIST KEHADIRAN'!A:H,5,FALSE) -> DR SALIMAH BINTI HJ OTHMAN | D65: =VLOOKUP(E65,'LIST KEHADIRAN'!A:H,8,FALSE) -> IKAN | E65: BR2
B66: 3 | C66: =VLOOKUP(E66,'LIST KEHADIRAN'!A:H,5,FALSE) -> MEJ YUSRI BIN DARUS | D66: =VLOOKUP(E66,'LIST KEHADIRAN'!A:H,8,FALSE) -> DAGING | E66: BR3
B67: 4 | C67: =VLOOKUP(E67,'LIST KEHADIRAN'!A:H,5,FALSE) -> MEJ JUHAIRI RAFHAN BIN JASMANI | D67: =VLOOKUP(E67,'LIST KEHADIRAN'!A:H,8,FALSE) -> KAMBING | E67: BR4
B68: 5 | C68: =VLOOKUP(E68,'LIST KEHADIRAN'!A:H,5,FALSE) -> MEJ MAZIAH BTE ABDUL MANAF | D68: =VLOOKUP(E68,'LIST KEHADIRAN'!A:H,8,FALSE) -> DAGING | E68: BR5
B69: 6 | C69: =VLOOKUP(E69,'LIST KEHADIRAN'!A:H,5,FALSE) -> KAPT NOOR ERMA SUZIANA BTE ABD MALIK | D69: =VLOOKUP(E69,'LIST KEHADIRAN'!A:H,8,FALSE) -> KAMBING | E69: BR6
B70: 7 | C70: =VLOOKUP(E70,'LIST KEHADIRAN'!A:H,5,FALSE) -> KAPT SELIA ANAK LISA | D70: =VLOOKUP(E70,'LIST KEHADIRAN'!A:H,8,FALSE) -> IKAN | E70: BR7
B71: 8 | C71: =VLOOKUP(E71,'LIST KEHADIRAN'!A:H,5,FALSE) -> #N/A | D71: =VLOOKUP(E71,'LIST KEHADIRAN'!A:H,8,FALSE) -> #N/A | E71: BR8
B72: 9 | C72: =VLOOKUP(E72,'LIST KEHADIRAN'!A:H,5,FALSE) -> #N/A | D72: =VLOOKUP(E72,'LIST KEHADIRAN'!A:H,8,FALSE) -> #N/A | E72: BR9
...

Sheet LIST KEHADIRAN
B1: BIL | C1: NO TEN | D1: PKT | E1: NAMA PENUH | F1: MEJA | G1: JAWATAN | H1: MENU
A2: =F2 -> 3 | B2: 1 | C2: 3004463 | D2: BRIG JEN | E2: BRIG JEN ZAMZURI BIN HARUN | F2: 3 | G2: PENGARAH | H2: DAGING | X2: 0126210046 / 0129210046 | Y2: L
A3: =F3 -> 4 | B3: 1 | C3: P3004463 | E3: PN ZURYATI BINTI ZULKIFLI | F3: 4 | H3: AYAM | X3: 012-2442182 | Y3: L
A4: =F4 -> 5 | B4: 2 | C4: 3003652 | D4: BRIG JEN | E4: BRIG JEN AZAMAN BIN JAAFAR | F4: 5 | G4: KETUA PENGARAH BELANJAWAN | H4: KAMBING | X4: 012-6636811 | Y4: L
A5: =F5 -> 6 | B5: 2 | C5: P3003652 | E5: PN ARDINA SURIA BTE ABU BAKAR | F5: 6 | H5: DAGING | X5: 012-3996017 | Y5: L
A6: =F6 -> 7 | B6: 4 | C6: 3005715 | D6: KOL | E6: KOL MOHD LUTPI TAUFIK BIN CHE MAT MIN | F6: 7 | G6: TIMB PENGARAH | H6: KAMBING | X6: 012-6393950 | Y6: P
A7: =F7 -> 8 | B7: 4 | C7: P3005715 | E7: PN TENGKU ASMA IZANI BINTI DATO’ TENGKU AZIZ | F7: 8 | H7: IKAN | X7: 019-2364654 | Y7: L
A8: =F8 -> 9 | B8: 3 | C8: 3005059 | D8: KOL | E8: KOL ZULKIFLE BIN HASHIM | F8: 9 | G8: PENGARAH BELANJAWAN | H8: DAGING | X8: 012-2886720 | Y8: L
A9: =F9 -> 10 | B9: 3 | C9: P3005059 | E9: PN RAHIMAH BINTI ALAM SAH | F9: 10 | H9: DAGING | X9: 013-9837644 | Y9: L
A10: =F10 -> 11 | B10: 9 | C10: 3007255 | D10: LT KOL | E10: LT KOL AZHAR BIN AHMAD | F10: 11 | G10: PS 1 TURUS | H10: IKAN | X10: 019-9157255 | Y10: L
A11: =F11 -> 12 | B11: 9 | C11: P3007255 | E11: PN FADHILAH BINTI AHMAD | F11: 12 | H11: AYAM | X11: 012-6636811 | Y11: L
A12: =F12 -> AL1 | B12: 5 | C12: 3005397 | D12: LT KOL | E12: LT KOL NORAZILENA BINTI MOHAMAD NOR | F12: AL1 | G12: PS 1 KEWANGAN | H12: KAMBING | X12: 019-3597529 | Y12: L
A13: =F13 -> AL10 | B13: 55 | C13: P3010901 | E13: PN HAFIZAH BINTI MAHAMAD NAWAWI | F13: AL10 | H13: DAGING | X13: 012-3390189 | Y13: L
A14: =F14 -> AL11 | B14: 54 | C14: P3010893 | E14: PN NURSYAZWANI BINTI NAZRI | F14: AL11 | H14: AYAM | X14: 013-3866248 | Y14: P
A15: =F15 -> AL12 | B15: 54 | C15: 3010893 | D15: MEJ | E15: MEJ HASBULLAH BIN ISMAIL | F15: AL12 | G15: PS 2 GAJI & BELANJAWAN | H15: DAGING | X15: 012-6161017 | Y15: P
A16: =F16 -> AL2 | B16: 14 | C16: 3010206 | D16: LT KOL | E16: LT KOL NORSYAZURA BTE MUSA | F16: AL2 | G16: PS 1 KAJIAN | H16: DAGING | X16: 019-9369693 | Y16: L
A17: =F17 -> AL3 | B17: 14 | C17: P3010206 | E17: EN MOHAMAD JOHARI BIN ISMAIL | F17: AL3 | H17: DAGING | X17: 019-2818035 | Y17: L
A18: =F18 -> AL4 | B18: 48 | C18: 3010186 | D18: MEJ | E18: MEJ KHAIRIZAL BIN RAUOB | F18: AL4 | G18: PS 2 BELANJAWAN | H18: KAMBING | X18: 019-2773749 | Y18: L
A19: =F19 -> AL5 | B19: 27 | C19: 3007993 | D19: MEJ | E19: MEJ AHMAD LUFTI BIN BABA | F19: AL5 | G19: PS 2 TADBIR | H19: AYAM | X19: 019-2866709 | Y19: L
A20: =F20 -> AL6 | B20: 27 | C20: P3007993 | E20: PN NURUL AIN BINTI ZAKARIA | F20: AL6 | H20: IKAN | X20: 019-8157186 | Y20: L
A21: =F21 -> AL7 | B21: 57 | C21: 3011296 | D21: MEJ | E21: MEJ UMMI KALSOM BTE MOHD LIAS | F21: AL7 | G21: PS 2 PANJAR | H21: DAGING | X21: 019-3935967 | Y21: L
A22: =F22 -> AL8 | B22: 37 | C22: 3008905 | D22: MEJ | E22: MEJ HARTINI BTE MD AMIN | F22: AL8 | G22: PEMEGANG PANJAR ATM 101 | H22: IKAN | X22: 016-7795115 | Y22: L
A23: =F23 -> AL9 | B23: 55 | C23: 3010901 | D23: MEJ | E23: MEJ JAMADIL HALIM BIN AZMI BAZIR | F23: AL9 | G23: PS 2 BAYARAN | H23: KAMBING | X23: 017-4036270 | Y23: L
A24: =F24 -> AR1 | B24: 23 | C24: 3006377 | D24: MEJ | E24: MEJ ROSMAZIA BTE MUSTAPHA | F24: AR1 | G24: PS 2 GAJI | H24: IKAN | X24: 019-2703285 | Y24: P
A25: =F25 -> AR2 | B25: 24 | C25: 3006690 | D25: MEJ | E25: MEJ KU NORAZLINI BTE MOHD ALI | F25: AR2 | G25: PEGAWAI GAJI | H25: IKAN | X25: 013-3880206 | Y25: P
A26: =F26 -> AR3 | B26: 31 | C26: 3008056 | D26: MEJ | E26: MEJ NATASYA AINI BTE OSMAN | F26: AR3 | G26: PS 2 GAJI | H26: DAGING | X26: 012-3207329 | Y26: L
A27: =F27 -> AR4 | B27: 73 | C27: 3011288 | D27: KAPT | E27: KAPT NUR DIYANA BTE CHE OMAR | F27: AR4 | G27: PS 2 GAJI | H27: KAMBING | X27: 012-3290079/ 019-3356810 | Y27: P
A28: =F28 -> AR5 | B28: 74 | C28: 7518991 | D28: KAPT | E28: KAPT SUNAINI BINTI MOHD ALI | F28: AR5 | G28: PS 2 PERSONAL EMOLUMEN (PE) | H28: AYAM | X28: 013-2970933 | Y28: L
A29: =F29 -> AR6 | B29: 75 | C29: 3012281 | D29: KAPT | E29: KAPT NUR IZZATI BINTI ZAIDEL | F29: AR6 | G29: KETUA AUDIT STAR RATING | H29: DAGING | X29: 019-5819848 | Y29: L
A30: =F30 -> AR7 | B30: 75 | C30: P3012281 | E30: MEJ MUHAMMAD AIZAT BIN ABDUL RAHIM | F30: AR7 | H30: IKAN | X30: 019-9808001 | Y30: L
A31: =F31 -> AR8 | B31: 84 | C31: 3012481 | D31: KAPT | E31: KAPT MOHAMAD A'RIF BIN MOHAMED NOR | F31: AR8 | G31: PEG GAJI | H31: DAGING | X31: 012-3458032 | Y31: L
A32: =F32 -> BL1 | B32: 7 | C32: 3006672 | D32: LT KOL | E32: LT KOL AZARUL AZUAN BIN ABDULLAH | F32: BL1 | G32: PS 1 KEWANGAN | H32: KAMBING | X32: 019-2778499 | Y32: P
A33: =F33 -> BL2 | B33: 7 | C33: P3006672 | E33: PN RAPIDAH BINTI MAZLAN | F33: BL2 | H33: DAGING | X33: 012-8064838 | Y33: L
A34: =F34 -> BL3 | B34: 20 | C34: P3007228 | E34: PN ISMAWATI BTE IDRIS | F34: BL3 | H34: IKAN | X34: 012-6293911 | Y34: P
A35: =F35 -> BL4 | B35: 20 | C35: 3007228 | D35: LT KOL | E35: LT KOL NAZIRUDDIN BIN ISMAIL | F35: BL4 | G35: PS 2 PEMERIKSAAN | H35: KAMBING | X35: 012-2748747 | Y35: P
A36: =F36 -> BL5 | B36: 67 | C36: 7510166 | D36: MEJ | E36: MEJ SHAHIZAM BIN MOHD SHARIF | F36: BL5 | G36: PS 2 BELANJAWAN | H36: IKAN | X36: 019-3558476 | Y36: L
A37: =F37 -> BL6 | B37: 67 | C37: P7510166 | E37: KAPT NOR NIZAMIAH BINTI OTHMAN | F37: BL6 | H37: DAGING | X37: 019-2718508 | Y37: P
A38: =F38 -> BR1 | B38: 6 | C38: 3006393 | D38: LT KOL | E38: LT KOL JAMAL BIN SAPRI | F38: BR1 | G38: PS 1 BELANJAWAN | H38: KAMBING | X38: 019-2009985 | Y38: P
A39: =F39 -> BR2 | B39: 6 | C39: P3006393 | E39: DR SALIMAH BINTI HJ OTHMAN | F39: BR2 | H39: IKAN | X39: 019-3398922 | Y39: L
A40: =F40 -> BR3 | B40: 22 | C40: 3006374 | D40: MEJ | E40: MEJ YUSRI BIN DARUS | F40: BR3 | G40: PS 2 BELANJAWAN | H40: DAGING | X40: 013-4217171 | Y40: L
...
